Workbook

Sheet 발주양식
A1: 주문상품 | B1: 옵션명 | C1: 수량 | D1: 수령인 | E1: 연락처 | F1: 우편번호 | G1: 주소 | H1: 상세주소 | I1: 배송메시지 | J1: 단가 | K1: 주문금액
A2: ='sku 정보'!$G2 -> 오아커버넥마사지기-베이지 | B2: ='sku 정보'!$H2 -> A00959 | C2: ='sku 정보'!$I2 -> 9 | D2: 쿠팡벤더플렉스-오아 | E2: 010-6844-6871 | F2: 37876 | G2: 경상북도 포항시 남구 대송면 송덕로212번길 138 제8동호 | J2: ='sku 정보'!$J2 -> 58826 | K2: =$J2*$C2 -> 529434
A3: ='sku 정보'!$G3 -> 보아르스위프클링전용필터 | B3: ='sku 정보'!$H3 -> M00313 | C3: ='sku 정보'!$I3 -> 10 | D3: 쿠팡벤더플렉스-오아 | E3: 010-6844-6871 | F3: 37876 | G3: 경상북도 포항시 남구 대송면 송덕로212번길 138 제8동호 | J3: ='sku 정보'!$J3 -> 3283 | K3: =$J3*$C3 -> 32830
A4: ='sku 정보'!$G4 -> 오아슬림에어드라이기-블랙 | B4: ='sku 정보'!$H4 -> A01146 | C4: ='sku 정보'!$I4 -> 7 | D4: 쿠팡벤더플렉스-오아 | E4: 010-6844-6871 | F4: 37876 | G4: 경상북도 포항시 남구 대송면 송덕로212번길 138 제8동호 | J4: ='sku 정보'!$J4 -> 39396 | K4: =$J4*$C4 -> 275772
A5: ='sku 정보'!$G5 -> 오아아이스볼트맥스-베이지 | B5: ='sku 정보'!$H5 -> A01593 | C5: ='sku 정보'!$I5 -> 26 | D5: 쿠팡벤더플렉스-오아 | E5: 010-6844-6871 | F5: 37876 | G5: 경상북도 포항시 남구 대송면 송덕로212번길 138 제8동호 | J5: ='sku 정보'!$J5 -> 19966 | K5: =$J5*$C5 -> 519116
A6: ='sku 정보'!$G6 -> 오아무선뿌리볼륨고데기5000-베이지 | B6: ='sku 정보'!$H6 -> A01672 | C6: ='sku 정보'!$I6 -> 117 | D6: 쿠팡벤더플렉스-오아 | E6: 010-6844-6871 | F6: 37876 | G6: 경상북도 포항시 남구 대송면 송덕로212번길 138 제8동호 | J6: ='sku 정보'!$J6 -> 26733 | K6: =$J6*$C6 -> 3127761
A7: ='sku 정보'!$G7 -> 오아폴드Qi2-블랙 | B7: ='sku 정보'!$H7 -> A01471 | C7: ='sku 정보'!$I7 -> 14 | D7: 쿠팡벤더플렉스-오아 | E7: 010-6844-6871 | F7: 37876 | G7: 경상북도 포항시 남구 대송면 송덕로212번길 138 제8동호 | J7: ='sku 정보'!$J7 -> 32830 | K7: =$J7*$C7 -> 459620
A8: ='sku 정보'!$G8 -> 오아에어리스마트-화이트 | B8: ='sku 정보'!$H8 -> A01676 | C8: ='sku 정보'!$I8 -> 24 | D8: 쿠팡벤더플렉스-오아 | E8: 010-6844-6871 | F8: 37876 | G8: 경상북도 포항시 남구 대송면 송덕로212번길 138 제8동호 | J8: ='sku 정보'!$J8 -> 58960 | K8: =$J8*$C8 -> 1415040
A9: ='sku 정보'!$G9 -> 오아이지물결고데기-블루 | B9: ='sku 정보'!$H9 -> A01834 | C9: ='sku 정보'!$I9 -> 50 | D9: 쿠팡벤더플렉스-오아 | E9: 010-6844-6871 | F9: 37876 | G9: 경상북도 포항시 남구 대송면 송덕로212번길 138 제8동호 | J9: ='sku 정보'!$J9 -> 30016 | K9: =$J9*$C9 -> 1500800
A10: ='sku 정보'!$G10 -> 오아심플리고데기-아이보리 | B10: ='sku 정보'!$H10 -> A01974 | C10: ='sku 정보'!$I10 -> 26 | D10: 쿠팡벤더플렉스-오아 | E10: 010-6844-6871 | F10: 37876 | G10: 경상북도 포항시 남구 대송면 송덕로212번길 138 제8동호 | J10: ='sku 정보'!$J10 -> 18693 | K10: =$J10*$C10 -> 486018
A11: ='sku 정보'!$G11 -> 보아르위셀음식물처리기 | B11: ='sku 정보'!$H11 -> A02015 | C11: ='sku 정보'!$I11 -> 11 | D11: 쿠팡벤더플렉스-오아 | E11: 010-6844-6871 | F11: 37876 | G11: 경상북도 포항시 남구 대송면 송덕로212번길 138 제8동호 | J11: ='sku 정보'!$J11 -> 213060 | K11: =$J11*$C11 -> 2343660
A12: ='sku 정보'!$G12 -> 오아듀얼미스트맥스-클라우디블루 | B12: ='sku 정보'!$H12 -> A02362 | C12: ='sku 정보'!$I12 -> 8 | D12: 쿠팡벤더플렉스-오아 | E12: 010-6844-6871 | F12: 37876 | G12: 경상북도 포항시 남구 대송면 송덕로212번길 138 제8동호 | J12: ='sku 정보'!$J12 -> 23383 | K12: =$J12*$C12 -> 187064
A13: ='sku 정보'!$G13 -> 오아히트워머-핑크 | B13: ='sku 정보'!$H13 -> A02229 | C13: ='sku 정보'!$I13 -> 27 | D13: 쿠팡벤더플렉스-오아 | E13: 010-6844-6871 | F13: 37876 | G13: 경상북도 포항시 남구 대송면 송덕로212번길 138 제8동호 | J13: ='sku 정보'!$J13 -> 21976 | K13: =$J13*$C13 -> 593352
... A17: ='sku 정보'!$G17 -> 오아클린이스윙P-어비스블랙 | B17: ='sku 정보'!$H17 -> A02862 | C17: ='sku 정보'!$I17 -> 54 | D17: 쿠팡벤더플렉스-오아 | E17: 010-6844-6871 | F17: 37876 | G17: 경상북도 포항시 남구 대송면 송덕로212번길 138 제8동호 | J17: ='sku 정보'!$J17 -> 30016 | K17: =$J17*$C17 -> 1620864

Sheet sku 정보
A1: SKU# | B1: 상품명 | C1: 프로코드 | D1: 매입가 | F1: skuid(입력란) | G1: 제품명(수식) | H1: 옵션명(수식) | I1: 수량(입력란) | J1: 매입가(수식) | L1: 마진테이블 공급가 | M1: 매칭 | N1: 1.써플라이어허브>물류>발주SKU리스트>입고예정일>오늘검색
A2: 3636925 | B2: 오아안개가습기500 | C2: H0002 | D2: 25326 | F2: 50875168 | G2: =IFERROR(VLOOKUP($F2,$A:$B,2,0),0) -> 오아커버넥마사지기-베이지 | H2: =IFERROR(VLOOKUP($F2,$A:$D,3,0),0) -> A00959 | I2: 9 | J2: =IFERROR(VLOOKUP($F2,$A:$D,4,0),0) -> 58826 | L2: 25326 | M2: =D2=L2 -> TRUE | N2: 2.상품목록다운로드>발주번호,skuid,확정수량>다운로드
A3: 3636926 | B3: 오아무드가습기1000 | C3: W0009 | D3: 26666 | F3: 52204284 | G3: =IFERROR(VLOOKUP($F3,$A:$B,2,0),0) -> 보아르스위프클링전용필터 | H3: =IFERROR(VLOOKUP($F3,$A:$D,3,0),0) -> M00313 | I3: 10 | J3: =IFERROR(VLOOKUP($F3,$A:$D,4,0),0) -> 3283 | L3: 26666 | M3: =D3=L3 -> TRUE | N3: 3.발주번호별skuid와수량은왼쪽하늘색음영에붙혀넣기
A4: 3636927 | B4: 오아무드가습기500 | C4: W0010 | D4: 21976 | F4: 55462718 | G4: =IFERROR(VLOOKUP($F4,$A:$B,2,0),0) -> 오아슬림에어드라이기-블랙 | H4: =IFERROR(VLOOKUP($F4,$A:$D,3,0),0) -> A01146 | I4: 7 | J4: =IFERROR(VLOOKUP($F4,$A:$D,4,0),0) -> 39396 | L4: 21976 | M4: =D4=L4 -> TRUE | N4: 4.A~C열에skuid,전산명,프로코드백데이터만들어두었음
A5: 39415252 | B5: 오아플렌티스팀3L | C5: H0191 | D5: 72360 | F5: 58716097 | G5: =IFERROR(VLOOKUP($F5,$A:$B,2,0),0) -> 오아아이스볼트맥스-베이지 | H5: =IFERROR(VLOOKUP($F5,$A:$D,3,0),0) -> A01593 | I5: 26 | J5: =IFERROR(VLOOKUP($F5,$A:$D,4,0),0) -> 19966 | L5: 72360 | M5: =D5=L5 -> TRUE | N5: 5.발주양식sheet에주문상품,옵션명,수량은sku정보sheet에수식걸어두었음
A6: 19213859 | B6: 오아타워가습기 | C6: H0139 | D6: 85090 | F6: 60085614 | G6: =IFERROR(VLOOKUP($F6,$A:$B,2,0),0) -> 오아무선뿌리볼륨고데기5000-베이지 | H6: =IFERROR(VLOOKUP($F6,$A:$D,3,0),0) -> A01672 | I6: 117 | J6: =IFERROR(VLOOKUP($F6,$A:$D,4,0),0) -> 26733 | L6: 85090 | M6: =D6=L6 -> TRUE | N6: 6.1+1또는세트구성상품은프로코드지웠음(발주나오면프로코드확인필요)
A7: 20342327 | B7: 오아클라젯가습기 | C7: H0140 | D7: 58960 | F7: 61089339 | G7: =IFERROR(VLOOKUP($F7,$A:$B,2,0),0) -> 오아폴드Qi2-블랙 | H7: =IFERROR(VLOOKUP($F7,$A:$D,3,0),0) -> A01471 | I7: 14 | J7: =IFERROR(VLOOKUP($F7,$A:$D,4,0),0) -> 32830 | L7: 58960 | M7: =D7=L7 -> TRUE | N7: 7.상품목록다운로드에발주번호는발주제품구분하기위해서임
A8: 13004238 | B8: 오아엠젯가습기 | C8: H0039 | D8: 71690 | F8: 61199642 | G8: =IFERROR(VLOOKUP($F8,$A:$B,2,0),0) -> 오아에어리스마트-화이트 | H8: =IFERROR(VLOOKUP($F8,$A:$D,3,0),0) -> A01676 | I8: 24 | J8: =IFERROR(VLOOKUP($F8,$A:$D,4,0),0) -> 58960 | L8: 71690 | M8: =D8=L8 -> TRUE | N8: 8.위탁주문은기존처럼업체주문번호/매출처명/연락처/배송방식/물류창고등입력
A9: 20341619 | B9: 오아도트플러스가습기 | C9: H0134 | D9: 64990 | F9: 64330764 | G9: =IFERROR(VLOOKUP($F9,$A:$B,2,0),0) -> 오아이지물결고데기-블루 | H9: =IFERROR(VLOOKUP($F9,$A:$D,3,0),0) -> A01834 | I9: 50 | J9: =IFERROR(VLOOKUP($F9,$A:$D,4,0),0) -> 30016 | L9: 64990 | M9: =D9=L9 -> TRUE | N9: 9.엑셀파일업로드하면상품목록자동입력됨(단가및프로코드확인요망)-최근전산오류
A10: 11092035 | B10: 오아에어워셔 | C10: H0001 | D10: 61640 | F10: 64808932 | G10: =IFERROR(VLOOKUP($F10,$A:$B,2,0),0) -> 오아심플리고데기-아이보리 | H10: =IFERROR(VLOOKUP($F10,$A:$D,3,0),0) -> A01974 | I10: 26 | J10: =IFERROR(VLOOKUP($F10,$A:$D,4,0),0) -> 18693 | L10: 61640 | M10: =D10=L10 -> TRUE | N10: 10.엑셀파일업로드할때발주양식에입력된수량밑에0개수식걸린것들은모두지워주면됨
A11: 40852278 | B11: 오아플렌티플렛4L | C11: H0222 | D11: 40066 | F11: 65145714 | G11: =IFERROR(VLOOKUP($F11,$A:$B,2,0),0) -> 보아르위셀음식물처리기 | H11: =IFERROR(VLOOKUP($F11,$A:$D,3,0),0) -> A02015 | I11: 11 | J11: =IFERROR(VLOOKUP($F11,$A:$D,4,0),0) -> 213060 | L11: 40066 | M11: =D11=L11 -> TRUE | N11: 11.매입가는마진테이블new기준임,1+1의경우프로코드공란이며매입가는맞음
A12: 29266932 | B12: 오아IoT플러스가습기 | C12: H0126 | D12: 38056 | F12: 65933937 | G12: =IFERROR(VLOOKUP($F12,$A:$B,2,0),0) -> 오아듀얼미스트맥스-클라우디블루 | H12: =IFERROR(VLOOKUP($F12,$A:$D,3,0),0) -> A02362 | I12: 8 | J12: =IFERROR(VLOOKUP($F12,$A:$D,4,0),0) -> 23383 | L12: 38056 | M12: =D12=L12 -> TRUE
A13: 12586373 | B13: 오아리아가습기 | C13: H0041 | D13: 40736 | F13: 66358440 | G13: =IFERROR(VLOOKUP($F13,$A:$B,2,0),0) -> 오아히트워머-핑크 | H13: =IFERROR(VLOOKUP($F13,$A:$D,3,0),0) -> A02229 | I13: 27 | J13: =IFERROR(VLOOKUP($F13,$A:$D,4,0),0) -> 21976 | L13: 40736 | M13: =D13=L13 -> TRUE
A14: 11055651 | B14: 오아도트가습기 | C14: H0034 | D14: 45426 | F14: 66778787 | G14: =IFERROR(VLOOKUP($F14,$A:$B,2,0),0) -> 오아미니핏고데기-베이지 | H14: =IFERROR(VLOOKUP($F14,$A:$D,3,0),0) -> A02234 | I14: 8 | J14: =IFERROR(VLOOKUP($F14,$A:$D,4,0),0) -> 17353 | L14: 45426 | M14: =D14=L14 -> TRUE
A15: 38659485 | B15: 오아플렌티무드가습기 | C15: H0207 | D15: 36046 | F15: 68938743 | G15: =IFERROR(VLOOKUP($F15,$A:$B,2,0),0) -> 오아프리온무선고데기-핑크 | H15: =IFERROR(VLOOKUP($F15,$A:$D,3,0),0) -> A02459 | I15: 133 | J15: =IFERROR(VLOOKUP($F15,$A:$D,4,0),0) -> 33433 | L15: 36046 | M15: =D15=L15 -> TRUE
A16: 9567647 | B16: 오아안개가습기1000 | C16: H0022 | D16: 29413 | F16: 69770093 | G16: =IFERROR(VLOOKUP($F16,$A:$B,2,0),0) -> 오아효도손마사지기-블랙 | H16: =IFERROR(VLOOKUP($F16,$A:$D,3,0),0) -> A00298 | I16: 12 | J16: =IFERROR(VLOOKUP($F16,$A:$D,4,0),0) -> 40066 | L16: 29413 | M16: =D16=L16 -> TRUE
A17: 40180424 | B17: 오아이글루가습기 | C17: H0220 | D17: 30016 | F17: 72910681 | G17: =IFERROR(VLOOKUP($F17,$A:$B,2,0),0) -> 오아클린이스윙P-어비스블랙 | H17: =IFERROR(VLOOKUP($F17,$A:$D,3,0),0) -> A02862 | I17: 54 | J17: =IFERROR(VLOOKUP($F17,$A:$D,4,0),0) -> 30016 | L17: 30016 | M17: =D17=L17 -> TRUE
A18: 39228155 | B18: 오아베이직가습기 | C18: H0236 | D18: 30016 | G18: =IFERROR(VLOOKUP($F18,$A:$B,2,0),0) -> 0 | H18: =IFERROR(VLOOKUP($F18,$A:$D,3,0),0) -> 0 | J18: =IFERROR(VLOOKUP($F18,$A:$D,4,0),0) -> 0 | L18: 30016 | M18: =D18=L18 -> TRUE
A19: 38407975 | B19: 오아플렌티큐브가습기 | C19: H0217 | D19: 30016 | G19: =IFERROR(VLOOKUP($F19,$A:$B,2,0),0) -> 0 | H19: =IFERROR(VLOOKUP($F19,$A:$D,3,0),0) -> 0 | J19: =IFERROR(VLOOKUP($F19,$A:$D,4,0),0) -> 0 | L19: 30016 | M19: =D19=L19 -> TRUE
A20: 38545387 | B20: 오아플렌티브릭가습기 | C20: H0199 | D20: 26666 | G20: =IFERROR(VLOOKUP($F20,$A:$B,2,0),0) -> 0 | H20: =IFERROR(VLOOKUP($F20,$A:$D,3,0),0) -> 0 | J20: =IFERROR(VLOOKUP($F20,$A:$D,4,0),0) -> 0 | L20: 23383 | M20: =D20=L20 -> FALSE
A21: 18816827 | B21: 오아IoT무드가습기 | C21: H0083 | D21: 26666 | G21: =IFERROR(VLOOKUP($F21,$A:$B,2,0),0) -> 0 | H21: =IFERROR(VLOOKUP($F21,$A:$D,3,0),0) -> 0 | J21: =IFERROR(VLOOKUP($F21,$A:$D,4,0),0) -> 0 | L21: 26666 | M21: =D21=L21 -> TRUE
A22: 39278162 | B22: 오아듀얼포그무선가습기 | C22: H0205 | D22: 20033 | G22: =IFERROR(VLOOKUP($F22,$A:$B,2,0),0) -> 0 | H22: =IFERROR(VLOOKUP($F22,$A:$D,3,0),0) -> 0 | J22: =IFERROR(VLOOKUP($F22,$A:$D,4,0),0) -> 0 | L22: 20033 | M22: =D22=L22 -> TRUE
A23: 13100374 | B23: 오아센스S무선가습기 | C23: H0066 | D23: 21842 | G23: =IFERROR(VLOOKUP($F23,$A:$B,2,0),0) -> 0 | H23: =IFERROR(VLOOKUP($F23,$A:$D,3,0),0) -> 0 | J23: =IFERROR(VLOOKUP($F23,$A:$D,4,0),0) -> 0 | L23: 21842 | M23: =D23=L23 -> TRUE
A24: 10855225 | B24: 오아듀얼미스트무선가습기 | C24: H0046 | D24: 19966 | G24: =IFERROR(VLOOKUP($F24,$A:$B,2,0),0) -> 0 | H24: =IFERROR(VLOOKUP($F24,$A:$D,3,0),0) -> 0 | J24: =IFERROR(VLOOKUP($F24,$A:$D,4,0),0) -> 0 | L24: 19966 | M24: =D24=L24 -> TRUE
A25: 38490171 | B25: 오아스퀘어미니가습기-베이지 | C25: H0198 | D25: 14606 | G25: =IFERROR(VLOOKUP($F25,$A:$B,2,0),0) -> 0 | H25: =IFERROR(VLOOKUP($F25,$A:$D,3,0),0) -> 0 | J25: =IFERROR(VLOOKUP($F25,$A:$D,4,0),0) -> 0 | L25: 14606 | M25: =D25=L25 -> TRUE
A26: 38490170 | B26: 오아스퀘어미니가습기-화이트 | C26: H0197 | D26: 14606 | G26: =IFERROR(VLOOKUP($F26,$A:$B,2,0),0) -> 0 | H26: =IFERROR(VLOOKUP($F26,$A:$D,3,0),0) -> 0 | J26: =IFERROR(VLOOKUP($F26,$A:$D,4,0),0) -> 0 | L26: 14606 | M26: =D26=L26 -> TRUE
A27: 38417027 | B27: 오아캡슐가습기 | C27: H0243 | D27: 11926 | G27: =IFERROR(VLOOKUP($F27,$A:$B,2,0),0) -> 0 | H27: =IFERROR(VLOOKUP($F27,$A:$D,3,0),0) -> 0 | J27: =IFERROR(VLOOKUP($F27,$A:$D,4,0),0) -> 0 | L27: 11926 | M27: =D27=L27 -> TRUE
A28: 13099542 | B28: 오아센스C무선가습기 | C28: H0069 | D28: 11926 | G28: =IFERROR(VLOOKUP($F28,$A:$B,2,0),0) -> 0 | H28: =IFERROR(VLOOKUP($F28,$A:$D,3,0),0) -> 0 | J28: =IFERROR(VLOOKUP($F28,$A:$D,4,0),0) -> 0 | L28: 11926 | M28: =D28=L28 -> TRUE
A29: 10324264 | B29: 오아퓨어공기청정기-화이트 | C29: A0048 | D29: 23316 | G29: =IFERROR(VLOOKUP($F29,$A:$B,2,0),0) -> 0 | H29: =IFERROR(VLOOKUP($F29,$A:$D,3,0),0) -> 0 | J29: =IFERROR(VLOOKUP($F29,$A:$D,4,0),0) -> 0 | L29: 23316 | M29: =D29=L29 -> TRUE
... A37: 13473750 | B37: 오아클린이워터F | C37: O0022 | D37: 33366 | G37: =IFERROR(VLOOKUP($F37,$A:$B,2,0),0) -> 0 | H37: =IFERROR(VLOOKUP($F37,$A:$D,3,0),0) -> 0 | J37: =IFERROR(VLOOKUP($F37,$A:$D,4,0),0) -> 0 | L37: 33366 | M37: =D37=L37 -> TRUE
A38: 17014694 | B38: 오아클린이소프트+소프트칫솔모4p화이트 | C38: 0 | D38: 30083 | G38: =IFERROR(VLOOKUP($F38,$A:$B,2,0),0) -> 0 | H38: =IFERROR(VLOOKUP($F38,$A:$D,3,0),0) -> 0 | J38: =IFERROR(VLOOKUP($F38,$A:$D,4,0),0) -> 0 | L38: 30083 | M38: =D38=L38 -> TRUE
A39: 17014693 | B39: 오아클린이소프트+소프트칫솔모4p블랙 | C39: 0 | D39: 30083 | G39: =IFERROR(VLOOKUP($F39,$A:$B,2,0),0) -> 0 | H39: =IFERROR(VLOOKUP($F39,$A:$D,3,0),0) -> 0 | J39: =IFERROR(VLOOKUP($F39,$A:$D,4,0),0) -> 0 | L39: 30083 | M39: =D39=L39 -> TRUE
A40: 13101218 | B40: 오아클린이소프트R-블랙 | C40: O0018 | D40: 29346 | G40: =IFERROR(VLOOKUP($F40,$A:$B,2,0),0) -> 0 | H40: =IFERROR(VLOOKUP($F40,$A:$D,3,0),0) -> 0 | J40: =IFERROR(VLOOKUP($F40,$A:$D,4,0),0) -> 0 | L40: 29346 | M40: =D40=L40 -> TRUE
A41: 13101217 | B41: 오아클린이소프트R-화이트 | C41: O0017 | D41: 29346 | G41: =IFERROR(VLOOKUP($F41,$A:$B,2,0),0) -> 0 | H41: =IFERROR(VLOOKUP($F41,$A:$D,3,0),0) -> 0 | J41: =IFERROR(VLOOKUP($F41,$A:$D,4,0),0) -> 0 | L41: 29346 | M41: =D41=L41 -> TRUE
A42: 16981939 | B42: 오아클린이베어블루+핑크 | C42: M01154 | D42: 30552 | G42: =IFERROR(VLOOKUP($F42,$A:$B,2,0),0) -> 0 | H42: =IFERROR(VLOOKUP($F42,$A:$D,3,0),0) -> 0 | J42: =IFERROR(VLOOKUP($F42,$A:$D,4,0),0) -> 0 | L42: 30552 | M42: =D42=L42 -> TRUE
A43: 12846219 | B43: 오아클린이워터D | C43: O0021 | D43: 29346 | G43: =IFERROR(VLOOKUP($F43,$A:$B,2,0),0) -> 0 | H43: =IFERROR(VLOOKUP($F43,$A:$D,3,0),0) -> 0 | J43: =IFERROR(VLOOKUP($F43,$A:$D,4,0),0) -> 0 | L43: 29346 | M43: =D43=L43 -> TRUE
A44: 17398556 | B44: 오아클린이소프트B+칫솔모2Px2화이트 | C44: 0 | D44: 27336 | G44: =IFERROR(VLOOKUP($F44,$A:$B,2,0),0) -> 0 | H44: =IFERROR(VLOOKUP($F44,$A:$D,3,0),0) -> 0 | J44: =IFERROR(VLOOKUP($F44,$A:$D,4,0),0) -> 0 | L44: 27336 | M44: =D44=L44 -> TRUE
A45: 16972627 | B45: 오아클린이소프트b블랙+칫솔모4p블랙 | C45: 0 | D45: 27336 | G45: =IFERROR(VLOOKUP($F45,$A:$B,2,0),0) -> 0 | H45: =IFERROR(VLOOKUP($F45,$A:$D,3,0),0) -> 0 | J45: =IFERROR(VLOOKUP($F45,$A:$D,4,0),0) -> 0 | L45: 27336 | M45: =D45=L45 -> TRUE
A46: 12846215 | B46: 오아클린이워터B | C46: O0020 | D46: 26666 | G46: =IFERROR(VLOOKUP($F46,$A:$B,2,0),0) -> 0 | H46: =IFERROR(VLOOKUP($F46,$A:$D,3,0),0) -> 0 | J46: =IFERROR(VLOOKUP($F46,$A:$D,4,0),0) -> 0 | L46: 26666 | M46: =D46=L46 -> TRUE
A47: 39663616 | B47: 오아클린이워터S-화이트 | C47: O0050 | D47: 25326 | G47: =IFERROR(VLOOKUP($F47,$A:$B,2,0),0) -> 0 | H47: =IFERROR(VLOOKUP($F47,$A:$D,3,0),0) -> 0 | J47: =IFERROR(VLOOKUP($F47,$A:$D,4,0),0) -> 0 | L47: 25326 | M47: =D47=L47 -> TRUE
...
